## Failable Main再訪問

Rust のコードには数多くのエラー表現がありますが、標準ライブラリには、エラーを記述するための普遍的なトレイト `std::error::Error` があります。

スマートポインタの `Box` を使って、エラーを返すための共通の型として `Box<dyn std::error::Error>` を使うことができます。これは、特定の型を知らなくてもヒープ上のエラーを伝播して、高レベルで対話することができるようになるからです。

Tour of Rust の初期に、`main` がエラーを返すことを学びました。エラーデータ構造がRustの一般的な `Error` トレイトを実装していれば、プログラムで発生する可能性のあるほぼすべての種類のエラーを記述できる型を返すことができるようになった。

``` 
fn main() -> Result<(), Box<dyn std::error:Error>>
```

```
use core::fmt::Display;
use std::error::Error;

struct Pie;

#[derive(Debug)]
struct NotFreshError;

impl Display for NotFreshError {
    fn fmt(&self, f: &mut std::fmt::Formatter<'_>) -> std::fmt::Result {
        write!(f, "This pie is not fresh!")
    }
}

impl Error for NotFreshError {}

impl Pie {
    fn eat(&self) -> Result<(), Box<dyn Error>> {
        Err(Box::new(NotFreshError))
    }
}

fn main() -> Result<(), Box<dyn Error>> {
    let heap_pie = Box::new(Pie);
    heap_pie.eat()?;
    Ok(())
}
```